Workbook

Sheet INSTRUCTIONS
A1: Column A in the sheet has the right answer. Column B has a Participant's answer. In Column C, you need to rate how close they are, on a scale 0 to 3:
A3: 3 - same meaning and same phrasing (including alternative spellings)
A4: 2 - meaning is very similar but not identical
A5: 1 - meaning is only partly similar
A6: 0 - meaning is very different (not related or only very distantly related)
A8: For example, if A is “Climb on my back” and B is “hop on me”, they are very similar but not identical, so in C you type in “2”.
A9: On the other hand, if A is "Climb on my back" and B is "giving attention", in C you put "0" because it has nothing in common.
A10: If A is "Groom me" and B is "touch me", you can put 1 in C because grooming involves touching and thus the meaning is partly similar.
A11: See below for some more example ratings. Don’t overthink your ratings, go with your first impression.
A12: After reading the instructions here, please go to tab “Vocalisation” and do the ratings for all four participants, i.e. compare Participant 1’s answers (column B) to the Right Answer (column A) and evaluate their similarity in column C; then compare Participant 2’s answers (colum D) to the Right Answer (column A), … etc.
A13: Then complete the evaluation for the remaining two tabs (Ape1 and Ape 2). There are much fewer ratings there than in Vocalisations.
A14: Remember that in all cases, you compare a Participant’s answer to the Right Answer (column A).
... A18: EXAMPLE RATINGS
A19: Right answer | B19: Participant 1 | C19: Rating P1
A20: Climb on my back | B20: giving attention | C20: 0
A21: Groom me | B21: touch me | C21: 1
A22: Groom me | B22: groom me | C22: 3
A23: Climb on my back | B23: hug me | C23: 0
A24: Let's have sex | B24: fcuk me :D | C24: 2
A25: Give me that food | B25: gimme that food | C25: 3
A26: Climb on my back | B26: hop on me | C26: 2
A27: Give me that food | B27: share that food | C27: 2
A28: Groom me | B28: climb on me probably | C28: 0
A29: Groom me | B29: groom me | C29: 3
A30: Let's be friendly | B30: being submissive | C30: 0
A31: Give me that food | B31: pick me uuuup | C31: 0
... A69: eat | B69: Another tasty soup | C69: 1

Sheet Vocalizations
A1: Trial id | B1: Right answer | C1: Participant 1 | D1: Rating P1 | E1: Participant 2 | F1: Rating P2 | G1: Participant 3 | H1: Rating P3 | I1: Participant 4 | J1: Rating P4
A2: 1 | B2: gather | C2: I love you | D2: 0 | E2: i dont know | F2: 0 | G2: over there | H2: 0 | I2: talk | J2: 0
A3: 2 | B3: bad | C3: Yuck | D3: 0 | E3: Discusting | F3: 1 | G3: oh no | H3: 0 | I3: scare | J3: 0
A4: 3 | B4: big | C4: Understanding | D4: 0 | E4: entusiasm | F4: 0 | G4: big | H4: 3 | I4: sleep | J4: 0
A5: 4 | B5: dull | C5: Disatisfied | D5: 0 | E5: understand | F5: 0 | G5: tired | H5: 0 | I5: sleep | J5: 0
A6: 5 | B6: hunt | C6: Frustration | D6: 0 | E6: angry | F6: 0 | G6: waking up | H6: 0 | I6: scare | J6: 0
A7: 6 | B7: knife | C7: Fast/fighting | D7: 0 | E7: wind | F7: 0 | G7: fight | H7: 0 | I7: attention | J7: 0
A8: 7 | B8: man | C8: Shivers of disgust | D8: 0 | E8: angry | F8: 0 | G8: now | H8: 0 | I8: scare | J8: 0
A9: 8 | B9: meat | C9: Good food | D9: 1 | E9: angry eat | F9: 0 | G9: went that way | H9: 0 | I9: eat | J9: 0
A10: 9 | B10: one | C10: Short no | D10: 0 | E10: indeference | F10: 0 | G10: yes | H10: 0 | I10: eat | J10: 0
A11: 10 | B11: snake | C11: Hot | D11: 0 | E11: touch something hot | F11: 0 | G11: hissing snake | H11: 3 | I11: attention | J11: 0
A12: 11 | B12: that | C12: Mild agree | D12: 0 | E12: understand | F12: 0 | G12: surprise | H12: 0 | I12: attention | J12: 0
A13: 12 | B13: tiger | C13: Aggressive | D13: 0 | E13: animal attack | F13: 0 | G13: growl | H13: 0 | I13: scare | J13: 0
... A91: 90 | B91: small | C91: Do it | D91: 0 | E91: i dont know | F91: 0 | G91: quick | H91: 0 | I91: attention | J91: 0

Sheet Ape 1
A1: Trial Id | B1: Right answer | C1: Participant 1 | D1: Rating P1 | E1: Participant 2 | F1: Rating P2 | G1: Participant 3 | H1: Rating P3
A2: 1 | B2: Groom me | C2: Hold on | D2: 0 | E2: Scratching himself | F2: 0 | G2: check my back | H2: 2
A3: 2 | B3: Groom me | C3: sit here | D3: 0 | E3: Alert | F3: 0 | G3: its my territory | H3: 0
A4: 3 | B4: Carry me | C4: astonishment | D4: 0 | E4: Relaxation | F4: 0 | G4: feel comfy | H4: 0
A5: 4 | B5: Give me that food | C5: defending | D5: 0 | E5: Asks for something | F5: 1 | G5: attention pls | H5: 0
A6: 5 | B6: Groom me | C6: superiority | D6: 0 | E6: Asking someone to clean him | F6: 2 | G6: just scratching, feel comfy | H6: 0
A7: 6 | B7: Climb on my back | C7: get away | D7: 0 | E7: Cleaning his kid | F7: 0 | G7: poking | H7: 0
A8: 7 | B8: Move into a new position | C8: get down | D8: 0 | E8: Pushing him to climb up | F8: 0 | G8: keeping close | H8: 0
A9: 8 | B9: Give me that food | C9: eat | D9: 0 | E9: Seeing what he eats | F9: 0 | G9: checking what he's eating | H9: 0
A10: 9 | B10: Give me that food | C10: frienship | D10: 0 | E10: Cleans his partner | F10: 0 | G10: he's bored | H10: 0
A11: 10 | B11: Let's have sex | C11: get food | D11: 0 | E11: Sign of aggression | F11: 0 | G11: danger | H11: 0
A12: 11 | B12: Move away from me | C12: scare something | D12: 0 | E12: Tells him to go away | F12: 2 | G12: watch out | H12: 0
A13: 12 | B13: Climb on my back | C13: be careful | D13: 0 | E13: Playing | F13: 0 | G13: playing around | H13: 0
... A21: 20 | B21: Let's be friendly | C21: courtship | D21: 0 | E21: Telling him to come here | F21: 0 | G21: checking | H21: 0

Sheet Ape 2
A1: Trial Id | B1: Right answer | C1: Participant 1 | D1: Rating P1 | E1: Participant 2 | F1: Rating P2 | G1: Participant 3 | H1: Rating P3
A2: 1 | B2: Let's have sex | C2: Time for love? | D2: 2 | E2: fun | F2: 0 | G2: Hunting | H2: 0
A3: 2 | B3: Groom me | C3: Scratch me under my arm | D3: 1 | E3: fun | F3: 0 | G3: Sleepy | H3: 0
A4: 3 | B4: Give me that food | C4: Im hungry | D4: 0 | E4: fun | F4: 0 | G4: Let's go | H4: 0
A5: 4 | B5: Groom me | C5: Scratching side | D5: 0 | E5: power | F5: 0 | G5: Hungry | H5: 0
A6: 5 | B6: Groom me | C6: Scratch me here | D6: 1 | E6: fun | F6: 0 | G6: Tired | H6: 0
A7: 6 | B7: Climb on my back | C7: Caution | D7: 0 | E7: protect | F7: 0 | G7: Stop | H7: 0
A8: 7 | B8: Move into a new position | C8: Don't touch there? | D8: 0 | E8: play | F8: 0 | G8: Angry | H8: 0
A9: 8 | B9: Give me that food | C9: Food for me? | D9: 1 | E9: need food | F9: 1 | G9: Stop | H9: 0
A10: 9 | B10: Give me that food | C10: Hungry (Share?) | D10: 1 | E10: need food | F10: 1 | G10: Don't move | H10: 0
A11: 10 | B11: Groom me | C11: Stay away | D11: 0 | E11: searching food | F11: 0 | G11: Climbing on | H11: 0
A12: 11 | B12: Climb on my back | C12: Jump on my back | D12: 2 | E12: help | F12: 0 | G12: Danger | H12: 0
A13: 12 | B13: Climb on my back | C13: Hop on! | D13: 1 | E13: alert | F13: 0 | G13: Aware | H13: 0
... A21: 20 | B21: Give me that food | C21: Hungry | D21: 2 | E21: sympathy | F21: 0 | G21: Appreciation | H21: 0

Sheet Ape01
A1: Trial Id | B1: Right answer | C1: Participant 1 | D1: Rating P1 | E1: Participant 2 | F1: Rating P2 | G1: Participant 3 | H1: Rating P3
A2: 1 | B2: Groom me | C2: Hold on | D2: 0 | E2: Scratching himself | F2: 0 | G2: check my back | H2: 2
A3: 2 | B3: Groom me | C3: sit here | D3: 0 | E3: Alert | F3: 0 | G3: its my territory | H3: 0
A4: 3 | B4: Carry me | C4: astonishment | D4: 0 | E4: Relaxation | F4: 0 | G4: feel comfy | H4: 0
A5: 4 | B5: Give me that food | C5: defending | D5: 0 | E5: Asks for something | F5: 1 | G5: attention pls | H5: 0
A6: 5 | B6: Groom me | C6: superiority | D6: 0 | E6: Asking someone to clean him | F6: 2 | G6: just scratching, feel comfy | H6: 0
A7: 6 | B7: Climb on my back | C7: get away | D7: 0 | E7: Cleaning his kid | F7: 0 | G7: poking | H7: 0
A8: 7 | B8: Move into a new position | C8: get down | D8: 0 | E8: Pushing him to climb up | F8: 0 | G8: keeping close | H8: 0
A9: 8 | B9: Give me that food | C9: eat | D9: 0 | E9: Seeing what he eats | F9: 0 | G9: checking what he's eating | H9: 0
A10: 9 | B10: Give me that food | C10: frienship | D10: 0 | E10: Cleans his partner | F10: 0 | G10: he's bored | H10: 0
A11: 10 | B11: Let's have sex | C11: get food | D11: 0 | E11: Sign of aggression | F11: 0 | G11: danger | H11: 0
A12: 11 | B12: Move away from me | C12: scare something | D12: 0 | E12: Tells him to go away | F12: 2 | G12: watch out | H12: 0
A13: 12 | B13: Climb on my back | C13: be careful | D13: 0 | E13: Playing | F13: 0 | G13: playing around | H13: 0
... A21: 20 | B21: Let's be friendly | C21: courtship | D21: 0 | E21: Telling him to come here | F21: 0 | G21: checking | H21: 0

Sheet Ape02
A1: Trial Id | B1: Right answer | C1: Participant 1 | D1: Rating P1 | E1: Participant 2 | F1: Rating P2 | G1: Participant 3 | H1: Rating P3
A2: 1 | B2: Let's have sex | C2: Time for love? | D2: 2 | E2: fun | F2: 0 | G2: Hunting | H2: 0
A3: 2 | B3: Groom me | C3: Scratch me under my arm | D3: 1 | E3: fun | F3: 0 | G3: Sleepy | H3: 0
A4: 3 | B4: Give me that food | C4: Im hungry | D4: 0 | E4: fun | F4: 0 | G4: Let's go | H4: 0
A5: 4 | B5: Groom me | C5: Scratching side | D5: 0 | E5: power | F5: 0 | G5: Hungry | H5: 0
A6: 5 | B6: Groom me | C6: Scratch me here | D6: 1 | E6: fun | F6: 0 | G6: Tired | H6: 0
A7: 6 | B7: Climb on my back | C7: Caution | D7: 0 | E7: protect | F7: 0 | G7: Stop | H7: 0
A8: 7 | B8: Move into a new position | C8: Don't touch there? | D8: 0 | E8: play | F8: 0 | G8: Angry | H8: 0
A9: 8 | B9: Give me that food | C9: Food for me? | D9: 1 | E9: need food | F9: 1 | G9: Stop | H9: 0
A10: 9 | B10: Give me that food | C10: Hungry (Share?) | D10: 1 | E10: need food | F10: 1 | G10: Don't move | H10: 0
A11: 10 | B11: Groom me | C11: Stay away | D11: 0 | E11: searching food | F11: 0 | G11: Climbing on | H11: 0
A12: 11 | B12: Climb on my back | C12: Jump on my back | D12: 2 | E12: help | F12: 0 | G12: Danger | H12: 0
A13: 12 | B13: Climb on my back | C13: Hop on! | D13: 1 | E13: alert | F13: 0 | G13: Aware | H13: 0
... A21: 20 | B21: Give me that food | C21: Hungry | D21: 2 | E21: sympathy | F21: 0 | G21: Appreciation | H21: 0

Sheet Vocalizations_comparison
A1: =IF(Vocalizations!A1 <> Vocalizations_Sveta!A1 , CONCAT(CONCAT(Vocalizations!A1 , "|") , Vocalizations_Sveta!A1 ) , Vocalizations!A1) -> Trial id | B1: =IF(Vocalizations!B1 <> Vocalizations_Sveta!B1 , CONCAT(CONCAT(Vocalizations!B1 , "|") , Vocalizations_Sveta!B1 ) , Vocalizations!B1) -> Right answer | C1: =IF(Vocalizations!C1 <> Vocalizations_Sveta!C1 , CONCAT(CONCAT(Vocalizations!C1 , "|") , Vocalizations_Sveta!C1 ) , Vocalizations!C1) -> Participant 1 | D1: =IF(Vocalizations!D1 <> Vocalizations_Sveta!D1 , CONCAT(CONCAT(Vocalizations!D1 , "|") , Vocalizations_Sveta!D1 ) , Vocalizations!D1) -> Rating P1 | E1: =IF(Vocalizations!E1 <> Vocalizations_Sveta!E1 , CONCAT(CONCAT(Vocalizations!E1 , "|") , Vocalizations_Sveta!E1 ) , Vocalizations!E1) -> Participant 2 | F1: =IF(Vocalizations!F1 <> Vocalizations_Sveta!F1 , CONCAT(CONCAT(Vocalizations!F1 , "|") , Vocalizations_Sveta!F1 ) , Vocalizations!F1) -> Rating P2 | G1: =IF(Vocalizations!G1 <> Vocalizations_Sveta!G1 , CONCAT(CONCAT(Vocalizations!G1 , "|") , Vocalizations_Sveta!G1 ) , Vocalizations!G1) -> Participant 3 | H1: =IF(Vocalizations!H1 <> Vocalizations_Sveta!H1 , CONCAT(CONCAT(Vocalizations!H1 , "|") , Vocalizations_Sveta!H1 ) , Vocalizations!H1) -> Rating P3 | ... K1: =IF(Vocalizations!K1 <> Vocalizations_Sveta!K1 , CONCAT(CONCAT(Vocalizations!K1 , "|") , Vocalizations_Sveta!K1 ) , Vocalizations!K1)
A2: =IF(Vocalizations!A2 <> Vocalizations_Sveta!A2 , CONCAT(CONCAT(Vocalizations!A2 , "|") , Vocalizations_Sveta!A2 ) , Vocalizations!A2) -> 1 | B2: =IF(Vocalizations!B2 <> Vocalizations_Sveta!B2 , CONCAT(CONCAT(Vocalizations!B2 , "|") , Vocalizations_Sveta!B2 ) , Vocalizations!B2) -> gather | C2: =IF(Vocalizations!C2 <> Vocalizations_Sveta!C2 , CONCAT(CONCAT(Vocalizations!C2 , "|") , Vocalizations_Sveta!C2 ) , Vocalizations!C2) -> I love you | D2: =IF(Vocalizations!D2 <> Vocalizations_Sveta!D2 , CONCAT(CONCAT(Vocalizations!D2 , "|") , Vocalizations_Sveta!D2 ) , Vocalizations!D2) -> 0 | E2: =IF(Vocalizations!E2 <> Vocalizations_Sveta!E2 , CONCAT(CONCAT(Vocalizations!E2 , "|") , Vocalizations_Sveta!E2 ) , Vocalizations!E2) -> i dont know | F2: =IF(Vocalizations!F2 <> Vocalizations_Sveta!F2 , CONCAT(CONCAT(Vocalizations!F2 , "|") , Vocalizations_Sveta!F2 ) , Vocalizations!F2) -> 0 | G2: =IF(Vocalizations!G2 <> Vocalizations_Sveta!G2 , CONCAT(CONCAT(Vocalizations!G2 , "|") , Vocalizations_Sveta!G2 ) , Vocalizations!G2) -> over there | H2: =IF(Vocalizations!H2 <> Vocalizations_Sveta!H2 , CONCAT(CONCAT(Vocalizations!H2 , "|") , Vocalizations_Sveta!H2 ) , Vocalizations!H2) -> 0 | ... K2: =IF(Vocalizations!K2 <> Vocalizations_Sveta!K2 , CONCAT(CONCAT(Vocalizations!K2 , "|") , Vocalizations_Sveta!K2 ) , Vocalizations!K2)
A3: =IF(Vocalizations!A3 <> Vocalizations_Sveta!A3 , CONCAT(CONCAT(Vocalizations!A3 , "|") , Vocalizations_Sveta!A3 ) , Vocalizations!A3) -> 2 | B3: =IF(Vocalizations!B3 <> Vocalizations_Sveta!B3 , CONCAT(CONCAT(Vocalizations!B3 , "|") , Vocalizations_Sveta!B3 ) , Vocalizations!B3) -> bad | C3: =IF(Vocalizations!C3 <> Vocalizations_Sveta!C3 , CONCAT(CONCAT(Vocalizations!C3 , "|") , Vocalizations_Sveta!C3 ) , Vocalizations!C3) -> Yuck | D3: =IF(Vocalizations!D3 <> Vocalizations_Sveta!D3 , CONCAT(CONCAT(Vocalizations!D3 , "|") , Vocalizations_Sveta!D3 ) , Vocalizations!D3) -> 0 | E3: =IF(Vocalizations!E3 <> Vocalizations_Sveta!E3 , CONCAT(CONCAT(Vocalizations!E3 , "|") , Vocalizations_Sveta!E3 ) , Vocalizations!E3) -> Discusting | F3: =IF(Vocalizations!F3 <> Vocalizations_Sveta!F3 , CONCAT(CONCAT(Vocalizations!F3 , "|") , Vocalizations_Sveta!F3 ) , Vocalizations!F3) -> 1 | G3: =IF(Vocalizations!G3 <> Vocalizations_Sveta!G3 , CONCAT(CONCAT(Vocalizations!G3 , "|") , Vocalizations_Sveta!G3 ) , Vocalizations!G3) -> oh no|0 | H3: =IF(Vocalizations!H3 <> Vocalizations_Sveta!H3 , CONCAT(CONCAT(Vocalizations!H3 , "|") , Vocalizations_Sveta!H3 ) , Vocalizations!H3) -> 0 | ... K3: =IF(Vocalizations!K3 <> Vocalizations_Sveta!K3 , CONCAT(CONCAT(Vocalizations!K3 , "|") , Vocalizations_Sveta!K3 ) , Vocalizations!K3)
A4: =IF(Vocalizations!A4 <> Vocalizations_Sveta!A4 , CONCAT(CONCAT(Vocalizations!A4 , "|") , Vocalizations_Sveta!A4 ) , Vocalizations!A4) -> 3 | B4: =IF(Vocalizations!B4 <> Vocalizations_Sveta!B4 , CONCAT(CONCAT(Vocalizations!B4 , "|") , Vocalizations_Sveta!B4 ) , Vocalizations!B4) -> big | C4: =IF(Vocalizations!C4 <> Vocalizations_Sveta!C4 , CONCAT(CONCAT(Vocalizations!C4 , "|") , Vocalizations_Sveta!C4 ) , Vocalizations!C4) -> Understanding | D4: =IF(Vocalizations!D4 <> Vocalizations_Sveta!D4 , CONCAT(CONCAT(Vocalizations!D4 , "|") , Vocalizations_Sveta!D4 ) , Vocalizations!D4) -> 0 | E4: =IF(Vocalizations!E4 <> Vocalizations_Sveta!E4 , CONCAT(CONCAT(Vocalizations!E4 , "|") , Vocalizations_Sveta!E4 ) , Vocalizations!E4) -> entusiasm | F4: =IF(Vocalizations!F4 <> Vocalizations_Sveta!F4 , CONCAT(CONCAT(Vocalizations!F4 , "|") , Vocalizations_Sveta!F4 ) , Vocalizations!F4) -> 0 | G4: =IF(Vocalizations!G4 <> Vocalizations_Sveta!G4 , CONCAT(CONCAT(Vocalizations!G4 , "|") , Vocalizations_Sveta!G4 ) , Vocalizations!G4) -> big | H4: =IF(Vocalizations!H4 <> Vocalizations_Sveta!H4 , CONCAT(CONCAT(Vocalizations!H4 , "|") , Vocalizations_Sveta!H4 ) , Vocalizations!H4) -> 3 | ... K4: =IF(Vocalizations!K4 <> Vocalizations_Sveta!K4 , CONCAT(CONCAT(Vocalizations!K4 , "|") , Vocalizations_Sveta!K4 ) , Vocalizations!K4)
A5: =IF(Vocalizations!A5 <> Vocalizations_Sveta!A5 , CONCAT(CONCAT(Vocalizations!A5 , "|") , Vocalizations_Sveta!A5 ) , Vocalizations!A5) -> 4 | B5: =IF(Vocalizations!B5 <> Vocalizations_Sveta!B5 , CONCAT(CONCAT(Vocalizations!B5 , "|") , Vocalizations_Sveta!B5 ) , Vocalizations!B5) -> dull | C5: =IF(Vocalizations!C5 <> Vocalizations_Sveta!C5 , CONCAT(CONCAT(Vocalizations!C5 , "|") , Vocalizations_Sveta!C5 ) , Vocalizations!C5) -> Disatisfied | D5: =IF(Vocalizations!D5 <> Vocalizations_Sveta!D5 , CONCAT(CONCAT(Vocalizations!D5 , "|") , Vocalizations_Sveta!D5 ) , Vocalizations!D5) -> 0 | E5: =IF(Vocalizations!E5 <> Vocalizations_Sveta!E5 , CONCAT(CONCAT(Vocalizations!E5 , "|") , Vocalizations_Sveta!E5 ) , Vocalizations!E5) -> understand | F5: =IF(Vocalizations!F5 <> Vocalizations_Sveta!F5 , CONCAT(CONCAT(Vocalizations!F5 , "|") , Vocalizations_Sveta!F5 ) , Vocalizations!F5) -> 0 | G5: =IF(Vocalizations!G5 <> Vocalizations_Sveta!G5 , CONCAT(CONCAT(Vocalizations!G5 , "|") , Vocalizations_Sveta!G5 ) , Vocalizations!G5) -> tired | H5: =IF(Vocalizations!H5 <> Vocalizations_Sveta!H5 , CONCAT(CONCAT(Vocalizations!H5 , "|") , Vocalizations_Sveta!H5 ) , Vocalizations!H5) -> 0 | ... K5: =IF(Vocalizations!K5 <> Vocalizations_Sveta!K5 , CONCAT(CONCAT(Vocalizations!K5 , "|") , Vocalizations_Sveta!K5 ) , Vocalizations!K5)
A6: =IF(Vocalizations!A6 <> Vocalizations_Sveta!A6 , CONCAT(CONCAT(Vocalizations!A6 , "|") , Vocalizations_Sveta!A6 ) , Vocalizations!A6) -> 5 | B6: =IF(Vocalizations!B6 <> Vocalizations_Sveta!B6 , CONCAT(CONCAT(Vocalizations!B6 , "|") , Vocalizations_Sveta!B6 ) , Vocalizations!B6) -> hunt | C6: =IF(Vocalizations!C6 <> Vocalizations_Sveta!C6 , CONCAT(CONCAT(Vocalizations!C6 , "|") , Vocalizations_Sveta!C6 ) , Vocalizations!C6) -> Frustration | D6: =IF(Vocalizations!D6 <> Vocalizations_Sveta!D6 , CONCAT(CONCAT(Vocalizations!D6 , "|") , Vocalizations_Sveta!D6 ) , Vocalizations!D6) -> 0 | E6: =IF(Vocalizations!E6 <> Vocalizations_Sveta!E6 , CONCAT(CONCAT(Vocalizations!E6 , "|") , Vocalizations_Sveta!E6 ) , Vocalizations!E6) -> angry | F6: =IF(Vocalizations!F6 <> Vocalizations_Sveta!F6 , CONCAT(CONCAT(Vocalizations!F6 , "|") , Vocalizations_Sveta!F6 ) , Vocalizations!F6) -> 0 | G6: =IF(Vocalizations!G6 <> Vocalizations_Sveta!G6 , CONCAT(CONCAT(Vocalizations!G6 , "|") , Vocalizations_Sveta!G6 ) , Vocalizations!G6) -> waking up | H6: =IF(Vocalizations!H6 <> Vocalizations_Sveta!H6 , CONCAT(CONCAT(Vocalizations!H6 , "|") , Vocalizations_Sveta!H6 ) , Vocalizations!H6) -> 0 | ... K6: =IF(Vocalizations!K6 <> Vocalizations_Sveta!K6 , CONCAT(CONCAT(Vocalizations!K6 , "|") , Vocalizations_Sveta!K6 ) , Vocalizations!K6)
A7: =IF(Vocalizations!A7 <> Vocalizations_Sveta!A7 , CONCAT(CONCAT(Vocalizations!A7 , "|") , Vocalizations_Sveta!A7 ) , Vocalizations!A7) -> 6 | B7: =IF(Vocalizations!B7 <> Vocalizations_Sveta!B7 , CONCAT(CONCAT(Vocalizations!B7 , "|") , Vocalizations_Sveta!B7 ) , Vocalizations!B7) -> knife | C7: =IF(Vocalizations!C7 <> Vocalizations_Sveta!C7 , CONCAT(CONCAT(Vocalizations!C7 , "|") , Vocalizations_Sveta!C7 ) , Vocalizations!C7) -> Fast/fighting | D7: =IF(Vocalizations!D7 <> Vocalizations_Sveta!D7 , CONCAT(CONCAT(Vocalizations!D7 , "|") , Vocalizations_Sveta!D7 ) , Vocalizations!D7) -> 0 | E7: =IF(Vocalizations!E7 <> Vocalizations_Sveta!E7 , CONCAT(CONCAT(Vocalizations!E7 , "|") , Vocalizations_Sveta!E7 ) , Vocalizations!E7) -> wind | F7: =IF(Vocalizations!F7 <> Vocalizations_Sveta!F7 , CONCAT(CONCAT(Vocalizations!F7 , "|") , Vocalizations_Sveta!F7 ) , Vocalizations!F7) -> 0 | G7: =IF(Vocalizations!G7 <> Vocalizations_Sveta!G7 , CONCAT(CONCAT(Vocalizations!G7 , "|") , Vocalizations_Sveta!G7 ) , Vocalizations!G7) -> fight | H7: =IF(Vocalizations!H7 <> Vocalizations_Sveta!H7 , CONCAT(CONCAT(Vocalizations!H7 , "|") , Vocalizations_Sveta!H7 ) , Vocalizations!H7) -> 0 | ... K7: =IF(Vocalizations!K7 <> Vocalizations_Sveta!K7 , CONCAT(CONCAT(Vocalizations!K7 , "|") , Vocalizations_Sveta!K7 ) , Vocalizations!K7)
A8: =IF(Vocalizations!A8 <> Vocalizations_Sveta!A8 , CONCAT(CONCAT(Vocalizations!A8 , "|") , Vocalizations_Sveta!A8 ) , Vocalizations!A8) -> 7 | B8: =IF(Vocalizations!B8 <> Vocalizations_Sveta!B8 , CONCAT(CONCAT(Vocalizations!B8 , "|") , Vocalizations_Sveta!B8 ) , Vocalizations!B8) -> man | C8: =IF(Vocalizations!C8 <> Vocalizations_Sveta!C8 , CONCAT(CONCAT(Vocalizations!C8 , "|") , Vocalizations_Sveta!C8 ) , Vocalizations!C8) -> Shivers of disgust | D8: =IF(Vocalizations!D8 <> Vocalizations_Sveta!D8 , CONCAT(CONCAT(Vocalizations!D8 , "|") , Vocalizations_Sveta!D8 ) , Vocalizations!D8) -> 0 | E8: =IF(Vocalizations!E8 <> Vocalizations_Sveta!E8 , CONCAT(CONCAT(Vocalizations!E8 , "|") , Vocalizations_Sveta!E8 ) , Vocalizations!E8) -> angry | F8: =IF(Vocalizations!F8 <> Vocalizations_Sveta!F8 , CONCAT(CONCAT(Vocalizations!F8 , "|") , Vocalizations_Sveta!F8 ) , Vocalizations!F8) -> 0 | G8: =IF(Vocalizations!G8 <> Vocalizations_Sveta!G8 , CONCAT(CONCAT(Vocalizations!G8 , "|") , Vocalizations_Sveta!G8 ) , Vocalizations!G8) -> now | H8: =IF(Vocalizations!H8 <> Vocalizations_Sveta!H8 , CONCAT(CONCAT(Vocalizations!H8 , "|") , Vocalizations_Sveta!H8 ) , Vocalizations!H8) -> 0 | ... K8: =IF(Vocalizations!K8 <> Vocalizations_Sveta!K8 , CONCAT(CONCAT(Vocalizations!K8 , "|") , Vocalizations_Sveta!K8 ) , Vocalizations!K8)
A9: =IF(Vocalizations!A9 <> Vocalizations_Sveta!A9 , CONCAT(CONCAT(Vocalizations!A9 , "|") , Vocalizations_Sveta!A9 ) , Vocalizations!A9) -> 8 | B9: =IF(Vocalizations!B9 <> Vocalizations_Sveta!B9 , CONCAT(CONCAT(Vocalizations!B9 , "|") , Vocalizations_Sveta!B9 ) , Vocalizations!B9) -> meat | C9: =IF(Vocalizations!C9 <> Vocalizations_Sveta!C9 , CONCAT(CONCAT(Vocalizations!C9 , "|") , Vocalizations_Sveta!C9 ) , Vocalizations!C9) -> Good food | D9: =IF(Vocalizations!D9 <> Vocalizations_Sveta!D9 , CONCAT(CONCAT(Vocalizations!D9 , "|") , Vocalizations_Sveta!D9 ) , Vocalizations!D9) -> 1 | E9: =IF(Vocalizations!E9 <> Vocalizations_Sveta!E9 , CONCAT(CONCAT(Vocalizations!E9 , "|") , Vocalizations_Sveta!E9 ) , Vocalizations!E9) -> angry eat | F9: =IF(Vocalizations!F9 <> Vocalizations_Sveta!F9 , CONCAT(CONCAT(Vocalizations!F9 , "|") , Vocalizations_Sveta!F9 ) , Vocalizations!F9) -> 0 | G9: =IF(Vocalizations!G9 <> Vocalizations_Sveta!G9 , CONCAT(CONCAT(Vocalizations!G9 , "|") , Vocalizations_Sveta!G9 ) , Vocalizations!G9) -> went that way | H9: =IF(Vocalizations!H9 <> Vocalizations_Sveta!H9 , CONCAT(CONCAT(Vocalizations!H9 , "|") , Vocalizations_Sveta!H9 ) , Vocalizations!H9) -> 0 | ... K9: =IF(Vocalizations!K9 <> Vocalizations_Sveta!K9 , CONCAT(CONCAT(Vocalizations!K9 , "|") , Vocalizations_Sveta!K9 ) , Vocalizations!K9)
A10: =IF(Vocalizations!A10 <> Vocalizations_Sveta!A10 , CONCAT(CONCAT(Vocalizations!A10 , "|") , Vocalizations_Sveta!A10 ) , Vocalizations!A10) -> 9 | B10: =IF(Vocalizations!B10 <> Vocalizations_Sveta!B10 , CONCAT(CONCAT(Vocalizations!B10 , "|") , Vocalizations_Sveta!B10 ) , Vocalizations!B10) -> one | C10: =IF(Vocalizations!C10 <> Vocalizations_Sveta!C10 , CONCAT(CONCAT(Vocalizations!C10 , "|") , Vocalizations_Sveta!C10 ) , Vocalizations!C10) -> Short no | D10: =IF(Vocalizations!D10 <> Vocalizations_Sveta!D10 , CONCAT(CONCAT(Vocalizations!D10 , "|") , Vocalizations_Sveta!D10 ) , Vocalizations!D10) -> 0 | E10: =IF(Vocalizations!E10 <> Vocalizations_Sveta!E10 , CONCAT(CONCAT(Vocalizations!E10 , "|") , Vocalizations_Sveta!E10 ) , Vocalizations!E10) -> indeference | F10: =IF(Vocalizations!F10 <> Vocalizations_Sveta!F10 , CONCAT(CONCAT(Vocalizations!F10 , "|") , Vocalizations_Sveta!F10 ) , Vocalizations!F10) -> 0 | G10: =IF(Vocalizations!G10 <> Vocalizations_Sveta!G10 , CONCAT(CONCAT(Vocalizations!G10 , "|") , Vocalizations_Sveta!G10 ) , Vocalizations!G10) -> yes | H10: =IF(Vocalizations!H10 <> Vocalizations_Sveta!H10 , CONCAT(CONCAT(Vocalizations!H10 , "|") , Vocalizations_Sveta!H10 ) , Vocalizations!H10) -> 0 | ... K10: =IF(Vocalizations!K10 <> Vocalizations_Sveta!K10 , CONCAT(CONCAT(Vocalizations!K10 , "|") , Vocalizations_Sveta!K10 ) , Vocalizations!K10)
A11: =IF(Vocalizations!A11 <> Vocalizations_Sveta!A11 , CONCAT(CONCAT(Vocalizations!A11 , "|") , Vocalizations_Sveta!A11 ) , Vocalizations!A11) -> 10 | B11: =IF(Vocalizations!B11 <> Vocalizations_Sveta!B11 , CONCAT(CONCAT(Vocalizations!B11 , "|") , Vocalizations_Sveta!B11 ) , Vocalizations!B11) -> snake | C11: =IF(Vocalizations!C11 <> Vocalizations_Sveta!C11 , CONCAT(CONCAT(Vocalizations!C11 , "|") , Vocalizations_Sveta!C11 ) , Vocalizations!C11) -> Hot | D11: =IF(Vocalizations!D11 <> Vocalizations_Sveta!D11 , CONCAT(CONCAT(Vocalizations!D11 , "|") , Vocalizations_Sveta!D11 ) , Vocalizations!D11) -> 0 | E11: =IF(Vocalizations!E11 <> Vocalizations_Sveta!E11 , CONCAT(CONCAT(Vocalizations!E11 , "|") , Vocalizations_Sveta!E11 ) , Vocalizations!E11) -> touch something hot | F11: =IF(Vocalizations!F11 <> Vocalizations_Sveta!F11 , CONCAT(CONCAT(Vocalizations!F11 , "|") , Vocalizations_Sveta!F11 ) , Vocalizations!F11) -> 0 | G11: =IF(Vocalizations!G11 <> Vocalizations_Sveta!G11 , CONCAT(CONCAT(Vocalizations!G11 , "|") , Vocalizations_Sveta!G11 ) , Vocalizations!G11) -> hissing snake | H11: =IF(Vocalizations!H11 <> Vocalizations_Sveta!H11 , CONCAT(CONCAT(Vocalizations!H11 , "|") , Vocalizations_Sveta!H11 ) , Vocalizations!H11) -> 3 | ... K11: =IF(Vocalizations!K11 <> Vocalizations_Sveta!K11 , CONCAT(CONCAT(Vocalizations!K11 , "|") , Vocalizations_Sveta!K11 ) , Vocalizations!K11)
A12: =IF(Vocalizations!A12 <> Vocalizations_Sveta!A12 , CONCAT(CONCAT(Vocalizations!A12 , "|") , Vocalizations_Sveta!A12 ) , Vocalizations!A12) -> 11 | B12: =IF(Vocalizations!B12 <> Vocalizations_Sveta!B12 , CONCAT(CONCAT(Vocalizations!B12 , "|") , Vocalizations_Sveta!B12 ) , Vocalizations!B12) -> that | C12: =IF(Vocalizations!C12 <> Vocalizations_Sveta!C12 , CONCAT(CONCAT(Vocalizations!C12 , "|") , Vocalizations_Sveta!C12 ) , Vocalizations!C12) -> Mild agree | D12: =IF(Vocalizations!D12 <> Vocalizations_Sveta!D12 , CONCAT(CONCAT(Vocalizations!D12 , "|") , Vocalizations_Sveta!D12 ) , Vocalizations!D12) -> 0 | E12: =IF(Vocalizations!E12 <> Vocalizations_Sveta!E12 , CONCAT(CONCAT(Vocalizations!E12 , "|") , Vocalizations_Sveta!E12 ) , Vocalizations!E12) -> understand | F12: =IF(Vocalizations!F12 <> Vocalizations_Sveta!F12 , CONCAT(CONCAT(Vocalizations!F12 , "|") , Vocalizations_Sveta!F12 ) , Vocalizations!F12) -> 0 | G12: =IF(Vocalizations!G12 <> Vocalizations_Sveta!G12 , CONCAT(CONCAT(Vocalizations!G12 , "|") , Vocalizations_Sveta!G12 ) , Vocalizations!G12) -> surprise | H12: =IF(Vocalizations!H12 <> Vocalizations_Sveta!H12 , CONCAT(CONCAT(Vocalizations!H12 , "|") , Vocalizations_Sveta!H12 ) , Vocalizations!H12) -> 0 | ... K12: =IF(Vocalizations!K12 <> Vocalizations_Sveta!K12 , CONCAT(CONCAT(Vocalizations!K12 , "|") , Vocalizations_Sveta!K12 ) , Vocalizations!K12)
... A91: =IF(Vocalizations!A91 <> Vocalizations_Sveta!A91 , CONCAT(CONCAT(Vocalizations!A91 , "|") , Vocalizations_Sveta!A91 ) , Vocalizations!A91) -> 90 | B91: =IF(Vocalizations!B91 <> Vocalizations_Sveta!B91 , CONCAT(CONCAT(Vocalizations!B91 , "|") , Vocalizations_Sveta!B91 ) , Vocalizations!B91) -> small | C91: =IF(Vocalizations!C91 <> Vocalizations_Sveta!C91 , CONCAT(CONCAT(Vocalizations!C91 , "|") , Vocalizations_Sveta!C91 ) , Vocalizations!C91) -> Do it | D91: =IF(Vocalizations!D91 <> Vocalizations_Sveta!D91 , CONCAT(CONCAT(Vocalizations!D91 , "|") , Vocalizations_Sveta!D91 ) , Vocalizations!D91) -> 0 | E91: =IF(Vocalizations!E91 <> Vocalizations_Sveta!E91 , CONCAT(CONCAT(Vocalizations!E91 , "|") , Vocalizations_Sveta!E91 ) , Vocalizations!E91) -> i dont know | F91: =IF(Vocalizations!F91 <> Vocalizations_Sveta!F91 , CONCAT(CONCAT(Vocalizations!F91 , "|") , Vocalizations_Sveta!F91 ) , Vocalizations!F91) -> 0 | G91: =IF(Vocalizations!G91 <> Vocalizations_Sveta!G91 , CONCAT(CONCAT(Vocalizations!G91 , "|") , Vocalizations_Sveta!G91 ) , Vocalizations!G91) -> quick | H91: =IF(Vocalizations!H91 <> Vocalizations_Sveta!H91 , CONCAT(CONCAT(Vocalizations!H91 , "|") , Vocalizations_Sveta!H91 ) , Vocalizations!H91) -> 0 | ... K91: =IF(Vocalizations!K91 <> Vocalizations_Sveta!K91 , CONCAT(CONCAT(Vocalizations!K91 , "|") , Vocalizations_Sveta!K91 ) , Vocalizations!K91)

Sheet Ape1_Comparison
A1: =IF('Ape01'!A1 <> Ape01_Sveta!A1 , CONCAT(CONCAT('Ape01'!A1 , "|") , Ape01_Sveta!A1 ) , 'Ape01'!A1) -> Trial Id | B1: =IF('Ape01'!B1 <> Ape01_Sveta!B1 , CONCAT(CONCAT('Ape01'!B1 , "|") , Ape01_Sveta!B1 ) , 'Ape01'!B1) -> Right answer | C1: =IF('Ape01'!C1 <> Ape01_Sveta!C1 , CONCAT(CONCAT('Ape01'!C1 , "|") , Ape01_Sveta!C1 ) , 'Ape01'!C1) -> Participant 1 | D1: =IF('Ape01'!D1 <> Ape01_Sveta!D1 , CONCAT(CONCAT('Ape01'!D1 , "|") , Ape01_Sveta!D1 ) , 'Ape01'!D1) -> Rating P1 | E1: =IF('Ape01'!E1 <> Ape01_Sveta!E1 , CONCAT(CONCAT('Ape01'!E1 , "|") , Ape01_Sveta!E1 ) , 'Ape01'!E1) -> Participant 2 | F1: =IF('Ape01'!F1 <> Ape01_Sveta!F1 , CONCAT(CONCAT('Ape01'!F1 , "|") , Ape01_Sveta!F1 ) , 'Ape01'!F1) -> Rating P2 | G1: =IF('Ape01'!G1 <> Ape01_Sveta!G1 , CONCAT(CONCAT('Ape01'!G1 , "|") , Ape01_Sveta!G1 ) , 'Ape01'!G1) -> Participant 3 | H1: =IF('Ape01'!H1 <> Ape01_Sveta!H1 , CONCAT(CONCAT('Ape01'!H1 , "|") , Ape01_Sveta!H1 ) , 'Ape01'!H1) -> Rating P3 | ... K1: =IF('Ape01'!K1 <> Ape01_Sveta!K1 , CONCAT(CONCAT('Ape01'!K1 , "|") , Ape01_Sveta!K1 ) , 'Ape01'!K1)
A2: =IF('Ape01'!A2 <> Ape01_Sveta!A2 , CONCAT(CONCAT('Ape01'!A2 , "|") , Ape01_Sveta!A2 ) , 'Ape01'!A2) -> 1 | B2: =IF('Ape01'!B2 <> Ape01_Sveta!B2 , CONCAT(CONCAT('Ape01'!B2 , "|") , Ape01_Sveta!B2 ) , 'Ape01'!B2) -> Groom me | C2: =IF('Ape01'!C2 <> Ape01_Sveta!C2 , CONCAT(CONCAT('Ape01'!C2 , "|") , Ape01_Sveta!C2 ) , 'Ape01'!C2) -> Hold on | D2: =IF('Ape01'!D2 <> Ape01_Sveta!D2 , CONCAT(CONCAT('Ape01'!D2 , "|") , Ape01_Sveta!D2 ) , 'Ape01'!D2) -> 0 | E2: =IF('Ape01'!E2 <> Ape01_Sveta!E2 , CONCAT(CONCAT('Ape01'!E2 , "|") , Ape01_Sveta!E2 ) , 'Ape01'!E2) -> Scratching himself | F2: =IF('Ape01'!F2 <> Ape01_Sveta!F2 , CONCAT(CONCAT('Ape01'!F2 , "|") , Ape01_Sveta!F2 ) , 'Ape01'!F2) -> 0 | G2: =IF('Ape01'!G2 <> Ape01_Sveta!G2 , CONCAT(CONCAT('Ape01'!G2 , "|") , Ape01_Sveta!G2 ) , 'Ape01'!G2) -> check my back | H2: =IF('Ape01'!H2 <> Ape01_Sveta!H2 , CONCAT(CONCAT('Ape01'!H2 , "|") , Ape01_Sveta!H2 ) , 'Ape01'!H2) -> 2 | ... K2: =IF('Ape01'!K2 <> Ape01_Sveta!K2 , CONCAT(CONCAT('Ape01'!K2 , "|") , Ape01_Sveta!K2 ) , 'Ape01'!K2)
A3: =IF('Ape01'!A3 <> Ape01_Sveta!A3 , CONCAT(CONCAT('Ape01'!A3 , "|") , Ape01_Sveta!A3 ) , 'Ape01'!A3) -> 2 | B3: =IF('Ape01'!B3 <> Ape01_Sveta!B3 , CONCAT(CONCAT('Ape01'!B3 , "|") , Ape01_Sveta!B3 ) , 'Ape01'!B3) -> Groom me | C3: =IF('Ape01'!C3 <> Ape01_Sveta!C3 , CONCAT(CONCAT('Ape01'!C3 , "|") , Ape01_Sveta!C3 ) , 'Ape01'!C3) -> sit here | D3: =IF('Ape01'!D3 <> Ape01_Sveta!D3 , CONCAT(CONCAT('Ape01'!D3 , "|") , Ape01_Sveta!D3 ) , 'Ape01'!D3) -> 0 | E3: =IF('Ape01'!E3 <> Ape01_Sveta!E3 , CONCAT(CONCAT('Ape01'!E3 , "|") , Ape01_Sveta!E3 ) , 'Ape01'!E3) -> Alert | F3: =IF('Ape01'!F3 <> Ape01_Sveta!F3 , CONCAT(CONCAT('Ape01'!F3 , "|") , Ape01_Sveta!F3 ) , 'Ape01'!F3) -> 0 | G3: =IF('Ape01'!G3 <> Ape01_Sveta!G3 , CONCAT(CONCAT('Ape01'!G3 , "|") , Ape01_Sveta!G3 ) , 'Ape01'!G3) -> its my territory | H3: =IF('Ape01'!H3 <> Ape01_Sveta!H3 , CONCAT(CONCAT('Ape01'!H3 , "|") , Ape01_Sveta!H3 ) , 'Ape01'!H3) -> 0 | ... K3: =IF('Ape01'!K3 <> Ape01_Sveta!K3 , CONCAT(CONCAT('Ape01'!K3 , "|") , Ape01_Sveta!K3 ) , 'Ape01'!K3)
A4: =IF('Ape01'!A4 <> Ape01_Sveta!A4 , CONCAT(CONCAT('Ape01'!A4 , "|") , Ape01_Sveta!A4 ) , 'Ape01'!A4) -> 3 | B4: =IF('Ape01'!B4 <> Ape01_Sveta!B4 , CONCAT(CONCAT('Ape01'!B4 , "|") , Ape01_Sveta!B4 ) , 'Ape01'!B4) -> Carry me | C4: =IF('Ape01'!C4 <> Ape01_Sveta!C4 , CONCAT(CONCAT('Ape01'!C4 , "|") , Ape01_Sveta!C4 ) , 'Ape01'!C4) -> astonishment | D4: =IF('Ape01'!D4 <> Ape01_Sveta!D4 , CONCAT(CONCAT('Ape01'!D4 , "|") , Ape01_Sveta!D4 ) , 'Ape01'!D4) -> 0 | E4: =IF('Ape01'!E4 <> Ape01_Sveta!E4 , CONCAT(CONCAT('Ape01'!E4 , "|") , Ape01_Sveta!E4 ) , 'Ape01'!E4) -> Relaxation | F4: =IF('Ape01'!F4 <> Ape01_Sveta!F4 , CONCAT(CONCAT('Ape01'!F4 , "|") , Ape01_Sveta!F4 ) , 'Ape01'!F4) -> 0 | G4: =IF('Ape01'!G4 <> Ape01_Sveta!G4 , CONCAT(CONCAT('Ape01'!G4 , "|") , Ape01_Sveta!G4 ) , 'Ape01'!G4) -> feel comfy | H4: =IF('Ape01'!H4 <> Ape01_Sveta!H4 , CONCAT(CONCAT('Ape01'!H4 , "|") , Ape01_Sveta!H4 ) , 'Ape01'!H4) -> 0 | ... K4: =IF('Ape01'!K4 <> Ape01_Sveta!K4 , CONCAT(CONCAT('Ape01'!K4 , "|") , Ape01_Sveta!K4 ) , 'Ape01'!K4)
A5: =IF('Ape01'!A5 <> Ape01_Sveta!A5 , CONCAT(CONCAT('Ape01'!A5 , "|") , Ape01_Sveta!A5 ) , 'Ape01'!A5) -> 4 | B5: =IF('Ape01'!B5 <> Ape01_Sveta!B5 , CONCAT(CONCAT('Ape01'!B5 , "|") , Ape01_Sveta!B5 ) , 'Ape01'!B5) -> Give me that food | C5: =IF('Ape01'!C5 <> Ape01_Sveta!C5 , CONCAT(CONCAT('Ape01'!C5 , "|") , Ape01_Sveta!C5 ) , 'Ape01'!C5) -> defending | D5: =IF('Ape01'!D5 <> Ape01_Sveta!D5 , CONCAT(CONCAT('Ape01'!D5 , "|") , Ape01_Sveta!D5 ) , 'Ape01'!D5) -> 0 | E5: =IF('Ape01'!E5 <> Ape01_Sveta!E5 , CONCAT(CONCAT('Ape01'!E5 , "|") , Ape01_Sveta!E5 ) , 'Ape01'!E5) -> Asks for something | F5: =IF('Ape01'!F5 <> Ape01_Sveta!F5 , CONCAT(CONCAT('Ape01'!F5 , "|") , Ape01_Sveta!F5 ) , 'Ape01'!F5) -> 1|0 | G5: =IF('Ape01'!G5 <> Ape01_Sveta!G5 , CONCAT(CONCAT('Ape01'!G5 , "|") , Ape01_Sveta!G5 ) , 'Ape01'!G5) -> attention pls | H5: =IF('Ape01'!H5 <> Ape01_Sveta!H5 , CONCAT(CONCAT('Ape01'!H5 , "|") , Ape01_Sveta!H5 ) , 'Ape01'!H5) -> 0 | ... K5: =IF('Ape01'!K5 <> Ape01_Sveta!K5 , CONCAT(CONCAT('Ape01'!K5 , "|") , Ape01_Sveta!K5 ) , 'Ape01'!K5)
A6: =IF('Ape01'!A6 <> Ape01_Sveta!A6 , CONCAT(CONCAT('Ape01'!A6 , "|") , Ape01_Sveta!A6 ) , 'Ape01'!A6) -> 5 | B6: =IF('Ape01'!B6 <> Ape01_Sveta!B6 , CONCAT(CONCAT('Ape01'!B6 , "|") , Ape01_Sveta!B6 ) , 'Ape01'!B6) -> Groom me | C6: =IF('Ape01'!C6 <> Ape01_Sveta!C6 , CONCAT(CONCAT('Ape01'!C6 , "|") , Ape01_Sveta!C6 ) , 'Ape01'!C6) -> superiority | D6: =IF('Ape01'!D6 <> Ape01_Sveta!D6 , CONCAT(CONCAT('Ape01'!D6 , "|") , Ape01_Sveta!D6 ) , 'Ape01'!D6) -> 0 | E6: =IF('Ape01'!E6 <> Ape01_Sveta!E6 , CONCAT(CONCAT('Ape01'!E6 , "|") , Ape01_Sveta!E6 ) , 'Ape01'!E6) -> Asking someone to clean him | F6: =IF('Ape01'!F6 <> Ape01_Sveta!F6 , CONCAT(CONCAT('Ape01'!F6 , "|") , Ape01_Sveta!F6 ) , 'Ape01'!F6) -> 2 | G6: =IF('Ape01'!G6 <> Ape01_Sveta!G6 , CONCAT(CONCAT('Ape01'!G6 , "|") , Ape01_Sveta!G6 ) , 'Ape01'!G6) -> just scratching, feel comfy | H6: =IF('Ape01'!H6 <> Ape01_Sveta!H6 , CONCAT(CONCAT('Ape01'!H6 , "|") , Ape01_Sveta!H6 ) , 'Ape01'!H6) -> 0 | ... K6: =IF('Ape01'!K6 <> Ape01_Sveta!K6 , CONCAT(CONCAT('Ape01'!K6 , "|") , Ape01_Sveta!K6 ) , 'Ape01'!K6)
A7: =IF('Ape01'!A7 <> Ape01_Sveta!A7 , CONCAT(CONCAT('Ape01'!A7 , "|") , Ape01_Sveta!A7 ) , 'Ape01'!A7) -> 6 | B7: =IF('Ape01'!B7 <> Ape01_Sveta!B7 , CONCAT(CONCAT('Ape01'!B7 , "|") , Ape01_Sveta!B7 ) , 'Ape01'!B7) -> Climb on my back | C7: =IF('Ape01'!C7 <> Ape01_Sveta!C7 , CONCAT(CONCAT('Ape01'!C7 , "|") , Ape01_Sveta!C7 ) , 'Ape01'!C7) -> get away | D7: =IF('Ape01'!D7 <> Ape01_Sveta!D7 , CONCAT(CONCAT('Ape01'!D7 , "|") , Ape01_Sveta!D7 ) , 'Ape01'!D7) -> 0 | E7: =IF('Ape01'!E7 <> Ape01_Sveta!E7 , CONCAT(CONCAT('Ape01'!E7 , "|") , Ape01_Sveta!E7 ) , 'Ape01'!E7) -> Cleaning his kid | F7: =IF('Ape01'!F7 <> Ape01_Sveta!F7 , CONCAT(CONCAT('Ape01'!F7 , "|") , Ape01_Sveta!F7 ) , 'Ape01'!F7) -> 0 | G7: =IF('Ape01'!G7 <> Ape01_Sveta!G7 , CONCAT(CONCAT('Ape01'!G7 , "|") , Ape01_Sveta!G7 ) , 'Ape01'!G7) -> poking | H7: =IF('Ape01'!H7 <> Ape01_Sveta!H7 , CONCAT(CONCAT('Ape01'!H7 , "|") , Ape01_Sveta!H7 ) , 'Ape01'!H7) -> 0 | ... K7: =IF('Ape01'!K7 <> Ape01_Sveta!K7 , CONCAT(CONCAT('Ape01'!K7 , "|") , Ape01_Sveta!K7 ) , 'Ape01'!K7)
A8: =IF('Ape01'!A8 <> Ape01_Sveta!A8 , CONCAT(CONCAT('Ape01'!A8 , "|") , Ape01_Sveta!A8 ) , 'Ape01'!A8) -> 7 | B8: =IF('Ape01'!B8 <> Ape01_Sveta!B8 , CONCAT(CONCAT('Ape01'!B8 , "|") , Ape01_Sveta!B8 ) , 'Ape01'!B8) -> Move into a new position | C8: =IF('Ape01'!C8 <> Ape01_Sveta!C8 , CONCAT(CONCAT('Ape01'!C8 , "|") , Ape01_Sveta!C8 ) , 'Ape01'!C8) -> get down | D8: =IF('Ape01'!D8 <> Ape01_Sveta!D8 , CONCAT(CONCAT('Ape01'!D8 , "|") , Ape01_Sveta!D8 ) , 'Ape01'!D8) -> 0 | E8: =IF('Ape01'!E8 <> Ape01_Sveta!E8 , CONCAT(CONCAT('Ape01'!E8 , "|") , Ape01_Sveta!E8 ) , 'Ape01'!E8) -> Pushing him to climb up | F8: =IF('Ape01'!F8 <> Ape01_Sveta!F8 , CONCAT(CONCAT('Ape01'!F8 , "|") , Ape01_Sveta!F8 ) , 'Ape01'!F8) -> 0 | G8: =IF('Ape01'!G8 <> Ape01_Sveta!G8 , CONCAT(CONCAT('Ape01'!G8 , "|") , Ape01_Sveta!G8 ) , 'Ape01'!G8) -> keeping close | H8: =IF('Ape01'!H8 <> Ape01_Sveta!H8 , CONCAT(CONCAT('Ape01'!H8 , "|") , Ape01_Sveta!H8 ) , 'Ape01'!H8) -> 0 | ... K8: =IF('Ape01'!K8 <> Ape01_Sveta!K8 , CONCAT(CONCAT('Ape01'!K8 , "|") , Ape01_Sveta!K8 ) , 'Ape01'!K8)
A9: =IF('Ape01'!A9 <> Ape01_Sveta!A9 , CONCAT(CONCAT('Ape01'!A9 , "|") , Ape01_Sveta!A9 ) , 'Ape01'!A9) -> 8 | B9: =IF('Ape01'!B9 <> Ape01_Sveta!B9 , CONCAT(CONCAT('Ape01'!B9 , "|") , Ape01_Sveta!B9 ) , 'Ape01'!B9) -> Give me that food | C9: =IF('Ape01'!C9 <> Ape01_Sveta!C9 , CONCAT(CONCAT('Ape01'!C9 , "|") , Ape01_Sveta!C9 ) , 'Ape01'!C9) -> eat | D9: =IF('Ape01'!D9 <> Ape01_Sveta!D9 , CONCAT(CONCAT('Ape01'!D9 , "|") , Ape01_Sveta!D9 ) , 'Ape01'!D9) -> 0 | E9: =IF('Ape01'!E9 <> Ape01_Sveta!E9 , CONCAT(CONCAT('Ape01'!E9 , "|") , Ape01_Sveta!E9 ) , 'Ape01'!E9) -> Seeing what he eats | F9: =IF('Ape01'!F9 <> Ape01_Sveta!F9 , CONCAT(CONCAT('Ape01'!F9 , "|") , Ape01_Sveta!F9 ) , 'Ape01'!F9) -> 0 | G9: =IF('Ape01'!G9 <> Ape01_Sveta!G9 , CONCAT(CONCAT('Ape01'!G9 , "|") , Ape01_Sveta!G9 ) , 'Ape01'!G9) -> checking what he's eating | H9: =IF('Ape01'!H9 <> Ape01_Sveta!H9 , CONCAT(CONCAT('Ape01'!H9 , "|") , Ape01_Sveta!H9 ) , 'Ape01'!H9) -> 0 | ... K9: =IF('Ape01'!K9 <> Ape01_Sveta!K9 , CONCAT(CONCAT('Ape01'!K9 , "|") , Ape01_Sveta!K9 ) , 'Ape01'!K9)
A10: =IF('Ape01'!A10 <> Ape01_Sveta!A10 , CONCAT(CONCAT('Ape01'!A10 , "|") , Ape01_Sveta!A10 ) , 'Ape01'!A10) -> 9 | B10: =IF('Ape01'!B10 <> Ape01_Sveta!B10 , CONCAT(CONCAT('Ape01'!B10 , "|") , Ape01_Sveta!B10 ) , 'Ape01'!B10) -> Give me that food | C10: =IF('Ape01'!C10 <> Ape01_Sveta!C10 , CONCAT(CONCAT('Ape01'!C10 , "|") , Ape01_Sveta!C10 ) , 'Ape01'!C10) -> frienship | D10: =IF('Ape01'!D10 <> Ape01_Sveta!D10 , CONCAT(CONCAT('Ape01'!D10 , "|") , Ape01_Sveta!D10 ) , 'Ape01'!D10) -> 0 | E10: =IF('Ape01'!E10 <> Ape01_Sveta!E10 , CONCAT(CONCAT('Ape01'!E10 , "|") , Ape01_Sveta!E10 ) , 'Ape01'!E10) -> Cleans his partner | F10: =IF('Ape01'!F10 <> Ape01_Sveta!F10 , CONCAT(CONCAT('Ape01'!F10 , "|") , Ape01_Sveta!F10 ) , 'Ape01'!F10) -> 0 | G10: =IF('Ape01'!G10 <> Ape01_Sveta!G10 , CONCAT(CONCAT('Ape01'!G10 , "|") , Ape01_Sveta!G10 ) , 'Ape01'!G10) -> he's bored | H10: =IF('Ape01'!H10 <> Ape01_Sveta!H10 , CONCAT(CONCAT('Ape01'!H10 , "|") , Ape01_Sveta!H10 ) , 'Ape01'!H10) -> 0 | ... K10: =IF('Ape01'!K10 <> Ape01_Sveta!K10 , CONCAT(CONCAT('Ape01'!K10 , "|") , Ape01_Sveta!K10 ) , 'Ape01'!K10)
A11: =IF('Ape01'!A11 <> Ape01_Sveta!A11 , CONCAT(CONCAT('Ape01'!A11 , "|") , Ape01_Sveta!A11 ) , 'Ape01'!A11) -> 10 | B11: =IF('Ape01'!B11 <> Ape01_Sveta!B11 , CONCAT(CONCAT('Ape01'!B11 , "|") , Ape01_Sveta!B11 ) , 'Ape01'!B11) -> Let's have sex | C11: =IF('Ape01'!C11 <> Ape01_Sveta!C11 , CONCAT(CONCAT('Ape01'!C11 , "|") , Ape01_Sveta!C11 ) , 'Ape01'!C11) -> get food | D11: =IF('Ape01'!D11 <> Ape01_Sveta!D11 , CONCAT(CONCAT('Ape01'!D11 , "|") , Ape01_Sveta!D11 ) , 'Ape01'!D11) -> 0 | E11: =IF('Ape01'!E11 <> Ape01_Sveta!E11 , CONCAT(CONCAT('Ape01'!E11 , "|") , Ape01_Sveta!E11 ) , 'Ape01'!E11) -> Sign of aggression | F11: =IF('Ape01'!F11 <> Ape01_Sveta!F11 , CONCAT(CONCAT('Ape01'!F11 , "|") , Ape01_Sveta!F11 ) , 'Ape01'!F11) -> 0 | G11: =IF('Ape01'!G11 <> Ape01_Sveta!G11 , CONCAT(CONCAT('Ape01'!G11 , "|") , Ape01_Sveta!G11 ) , 'Ape01'!G11) -> danger | H11: =IF('Ape01'!H11 <> Ape01_Sveta!H11 , CONCAT(CONCAT('Ape01'!H11 , "|") , Ape01_Sveta!H11 ) , 'Ape01'!H11) -> 0 | ... K11: =IF('Ape01'!K11 <> Ape01_Sveta!K11 , CONCAT(CONCAT('Ape01'!K11 , "|") , Ape01_Sveta!K11 ) , 'Ape01'!K11)
A12: =IF('Ape01'!A12 <> Ape01_Sveta!A12 , CONCAT(CONCAT('Ape01'!A12 , "|") , Ape01_Sveta!A12 ) , 'Ape01'!A12) -> 11 | B12: =IF('Ape01'!B12 <> Ape01_Sveta!B12 , CONCAT(CONCAT('Ape01'!B12 , "|") , Ape01_Sveta!B12 ) , 'Ape01'!B12) -> Move away from me | C12: =IF('Ape01'!C12 <> Ape01_Sveta!C12 , CONCAT(CONCAT('Ape01'!C12 , "|") , Ape01_Sveta!C12 ) , 'Ape01'!C12) -> scare something | D12: =IF('Ape01'!D12 <> Ape01_Sveta!D12 , CONCAT(CONCAT('Ape01'!D12 , "|") , Ape01_Sveta!D12 ) , 'Ape01'!D12) -> 0 | E12: =IF('Ape01'!E12 <> Ape01_Sveta!E12 , CONCAT(CONCAT('Ape01'!E12 , "|") , Ape01_Sveta!E12 ) , 'Ape01'!E12) -> Tells him to go away | F12: =IF('Ape01'!F12 <> Ape01_Sveta!F12 , CONCAT(CONCAT('Ape01'!F12 , "|") , Ape01_Sveta!F12 ) , 'Ape01'!F12) -> 2 | G12: =IF('Ape01'!G12 <> Ape01_Sveta!G12 , CONCAT(CONCAT('Ape01'!G12 , "|") , Ape01_Sveta!G12 ) , 'Ape01'!G12) -> watch out | H12: =IF('Ape01'!H12 <> Ape01_Sveta!H12 , CONCAT(CONCAT('Ape01'!H12 , "|") , Ape01_Sveta!H12 ) , 'Ape01'!H12) -> 0 | ... K12: =IF('Ape01'!K12 <> Ape01_Sveta!K12 , CONCAT(CONCAT('Ape01'!K12 , "|") , Ape01_Sveta!K12 ) , 'Ape01'!K12)
... A27: =IF('Ape01'!A27 <> Ape01_Sveta!A27 , CONCAT(CONCAT('Ape01'!A27 , "|") , Ape01_Sveta!A27 ) , 'Ape01'!A27) | B27: =IF('Ape01'!B27 <> Ape01_Sveta!B27 , CONCAT(CONCAT('Ape01'!B27 , "|") , Ape01_Sveta!B27 ) , 'Ape01'!B27) | C27: =IF('Ape01'!C27 <> Ape01_Sveta!C27 , CONCAT(CONCAT('Ape01'!C27 , "|") , Ape01_Sveta!C27 ) , 'Ape01'!C27) | D27: =IF('Ape01'!D27 <> Ape01_Sveta!D27 , CONCAT(CONCAT('Ape01'!D27 , "|") , Ape01_Sveta!D27 ) , 'Ape01'!D27) | E27: =IF('Ape01'!E27 <> Ape01_Sveta!E27 , CONCAT(CONCAT('Ape01'!E27 , "|") , Ape01_Sveta!E27 ) , 'Ape01'!E27) | F27: =IF('Ape01'!F27 <> Ape01_Sveta!F27 , CONCAT(CONCAT('Ape01'!F27 , "|") , Ape01_Sveta!F27 ) , 'Ape01'!F27) | G27: =IF('Ape01'!G27 <> Ape01_Sveta!G27 , CONCAT(CONCAT('Ape01'!G27 , "|") , Ape01_Sveta!G27 ) , 'Ape01'!G27) | H27: =IF('Ape01'!H27 <> Ape01_Sveta!H27 , CONCAT(CONCAT('Ape01'!H27 , "|") , Ape01_Sveta!H27 ) , 'Ape01'!H27) | ... K27: =IF('Ape01'!K27 <> Ape01_Sveta!K27 , CONCAT(CONCAT('Ape01'!K27 , "|") , Ape01_Sveta!K27 ) , 'Ape01'!K27)

Sheet Ape2_Comparison
A1: =IF('Ape02'!A1 <> Ape02_Sveta!A1 , CONCAT(CONCAT('Ape02'!A1 , "|") , Ape02_Sveta!A1 ) , 'Ape02'!A1) -> Trial Id | B1: =IF('Ape02'!B1 <> Ape02_Sveta!B1 , CONCAT(CONCAT('Ape02'!B1 , "|") , Ape02_Sveta!B1 ) , 'Ape02'!B1) -> Right answer | C1: =IF('Ape02'!C1 <> Ape02_Sveta!C1 , CONCAT(CONCAT('Ape02'!C1 , "|") , Ape02_Sveta!C1 ) , 'Ape02'!C1) -> Participant 1 | D1: =IF('Ape02'!D1 <> Ape02_Sveta!D1 , CONCAT(CONCAT('Ape02'!D1 , "|") , Ape02_Sveta!D1 ) , 'Ape02'!D1) -> Rating P1 | E1: =IF('Ape02'!E1 <> Ape02_Sveta!E1 , CONCAT(CONCAT('Ape02'!E1 , "|") , Ape02_Sveta!E1 ) , 'Ape02'!E1) -> Participant 2 | F1: =IF('Ape02'!F1 <> Ape02_Sveta!F1 , CONCAT(CONCAT('Ape02'!F1 , "|") , Ape02_Sveta!F1 ) , 'Ape02'!F1) -> Rating P2 | G1: =IF('Ape02'!G1 <> Ape02_Sveta!G1 , CONCAT(CONCAT('Ape02'!G1 , "|") , Ape02_Sveta!G1 ) , 'Ape02'!G1) -> Participant 3 | H1: =IF('Ape02'!H1 <> Ape02_Sveta!H1 , CONCAT(CONCAT('Ape02'!H1 , "|") , Ape02_Sveta!H1 ) , 'Ape02'!H1) -> Rating P3 | ... L1: =IF('Ape02'!L1 <> Ape02_Sveta!L1 , CONCAT(CONCAT('Ape02'!L1 , "|") , Ape02_Sveta!L1 ) , 'Ape02'!L1)
A2: =IF('Ape02'!A2 <> Ape02_Sveta!A2 , CONCAT(CONCAT('Ape02'!A2 , "|") , Ape02_Sveta!A2 ) , 'Ape02'!A2) -> 1 | B2: =IF('Ape02'!B2 <> Ape02_Sveta!B2 , CONCAT(CONCAT('Ape02'!B2 , "|") , Ape02_Sveta!B2 ) , 'Ape02'!B2) -> Let's have sex | C2: =IF('Ape02'!C2 <> Ape02_Sveta!C2 , CONCAT(CONCAT('Ape02'!C2 , "|") , Ape02_Sveta!C2 ) , 'Ape02'!C2) -> Time for love? | D2: =IF('Ape02'!D2 <> Ape02_Sveta!D2 , CONCAT(CONCAT('Ape02'!D2 , "|") , Ape02_Sveta!D2 ) , 'Ape02'!D2) -> 2 | E2: =IF('Ape02'!E2 <> Ape02_Sveta!E2 , CONCAT(CONCAT('Ape02'!E2 , "|") , Ape02_Sveta!E2 ) , 'Ape02'!E2) -> fun | F2: =IF('Ape02'!F2 <> Ape02_Sveta!F2 , CONCAT(CONCAT('Ape02'!F2 , "|") , Ape02_Sveta!F2 ) , 'Ape02'!F2) -> 0 | G2: =IF('Ape02'!G2 <> Ape02_Sveta!G2 , CONCAT(CONCAT('Ape02'!G2 , "|") , Ape02_Sveta!G2 ) , 'Ape02'!G2) -> Hunting | H2: =IF('Ape02'!H2 <> Ape02_Sveta!H2 , CONCAT(CONCAT('Ape02'!H2 , "|") , Ape02_Sveta!H2 ) , 'Ape02'!H2) -> 0 | ... L2: =IF('Ape02'!L2 <> Ape02_Sveta!L2 , CONCAT(CONCAT('Ape02'!L2 , "|") , Ape02_Sveta!L2 ) , 'Ape02'!L2)
A3: =IF('Ape02'!A3 <> Ape02_Sveta!A3 , CONCAT(CONCAT('Ape02'!A3 , "|") , Ape02_Sveta!A3 ) , 'Ape02'!A3) -> 2 | B3: =IF('Ape02'!B3 <> Ape02_Sveta!B3 , CONCAT(CONCAT('Ape02'!B3 , "|") , Ape02_Sveta!B3 ) , 'Ape02'!B3) -> Groom me | C3: =IF('Ape02'!C3 <> Ape02_Sveta!C3 , CONCAT(CONCAT('Ape02'!C3 , "|") , Ape02_Sveta!C3 ) , 'Ape02'!C3) -> Scratch me under my arm | D3: =IF('Ape02'!D3 <> Ape02_Sveta!D3 , CONCAT(CONCAT('Ape02'!D3 , "|") , Ape02_Sveta!D3 ) , 'Ape02'!D3) -> 1 | E3: =IF('Ape02'!E3 <> Ape02_Sveta!E3 , CONCAT(CONCAT('Ape02'!E3 , "|") , Ape02_Sveta!E3 ) , 'Ape02'!E3) -> fun | F3: =IF('Ape02'!F3 <> Ape02_Sveta!F3 , CONCAT(CONCAT('Ape02'!F3 , "|") , Ape02_Sveta!F3 ) , 'Ape02'!F3) -> 0 | G3: =IF('Ape02'!G3 <> Ape02_Sveta!G3 , CONCAT(CONCAT('Ape02'!G3 , "|") , Ape02_Sveta!G3 ) , 'Ape02'!G3) -> Sleepy | H3: =IF('Ape02'!H3 <> Ape02_Sveta!H3 , CONCAT(CONCAT('Ape02'!H3 , "|") , Ape02_Sveta!H3 ) , 'Ape02'!H3) -> 0 | ... L3: =IF('Ape02'!L3 <> Ape02_Sveta!L3 , CONCAT(CONCAT('Ape02'!L3 , "|") , Ape02_Sveta!L3 ) , 'Ape02'!L3)
A4: =IF('Ape02'!A4 <> Ape02_Sveta!A4 , CONCAT(CONCAT('Ape02'!A4 , "|") , Ape02_Sveta!A4 ) , 'Ape02'!A4) -> 3 | B4: =IF('Ape02'!B4 <> Ape02_Sveta!B4 , CONCAT(CONCAT('Ape02'!B4 , "|") , Ape02_Sveta!B4 ) , 'Ape02'!B4) -> Give me that food | C4: =IF('Ape02'!C4 <> Ape02_Sveta!C4 , CONCAT(CONCAT('Ape02'!C4 , "|") , Ape02_Sveta!C4 ) , 'Ape02'!C4) -> Im hungry | D4: =IF('Ape02'!D4 <> Ape02_Sveta!D4 , CONCAT(CONCAT('Ape02'!D4 , "|") , Ape02_Sveta!D4 ) , 'Ape02'!D4) -> 0 | E4: =IF('Ape02'!E4 <> Ape02_Sveta!E4 , CONCAT(CONCAT('Ape02'!E4 , "|") , Ape02_Sveta!E4 ) , 'Ape02'!E4) -> fun | F4: =IF('Ape02'!F4 <> Ape02_Sveta!F4 , CONCAT(CONCAT('Ape02'!F4 , "|") , Ape02_Sveta!F4 ) , 'Ape02'!F4) -> 0 | G4: =IF('Ape02'!G4 <> Ape02_Sveta!G4 , CONCAT(CONCAT('Ape02'!G4 , "|") , Ape02_Sveta!G4 ) , 'Ape02'!G4) -> Let's go | H4: =IF('Ape02'!H4 <> Ape02_Sveta!H4 , CONCAT(CONCAT('Ape02'!H4 , "|") , Ape02_Sveta!H4 ) , 'Ape02'!H4) -> 0 | ... L4: =IF('Ape02'!L4 <> Ape02_Sveta!L4 , CONCAT(CONCAT('Ape02'!L4 , "|") , Ape02_Sveta!L4 ) , 'Ape02'!L4)
A5: =IF('Ape02'!A5 <> Ape02_Sveta!A5 , CONCAT(CONCAT('Ape02'!A5 , "|") , Ape02_Sveta!A5 ) , 'Ape02'!A5) -> 4 | B5: =IF('Ape02'!B5 <> Ape02_Sveta!B5 , CONCAT(CONCAT('Ape02'!B5 , "|") , Ape02_Sveta!B5 ) , 'Ape02'!B5) -> Groom me | C5: =IF('Ape02'!C5 <> Ape02_Sveta!C5 , CONCAT(CONCAT('Ape02'!C5 , "|") , Ape02_Sveta!C5 ) , 'Ape02'!C5) -> Scratching side | D5: =IF('Ape02'!D5 <> Ape02_Sveta!D5 , CONCAT(CONCAT('Ape02'!D5 , "|") , Ape02_Sveta!D5 ) , 'Ape02'!D5) -> 0 | E5: =IF('Ape02'!E5 <> Ape02_Sveta!E5 , CONCAT(CONCAT('Ape02'!E5 , "|") , Ape02_Sveta!E5 ) , 'Ape02'!E5) -> power | F5: =IF('Ape02'!F5 <> Ape02_Sveta!F5 , CONCAT(CONCAT('Ape02'!F5 , "|") , Ape02_Sveta!F5 ) , 'Ape02'!F5) -> 0 | G5: =IF('Ape02'!G5 <> Ape02_Sveta!G5 , CONCAT(CONCAT('Ape02'!G5 , "|") , Ape02_Sveta!G5 ) , 'Ape02'!G5) -> Hungry | H5: =IF('Ape02'!H5 <> Ape02_Sveta!H5 , CONCAT(CONCAT('Ape02'!H5 , "|") , Ape02_Sveta!H5 ) , 'Ape02'!H5) -> 0 | ... L5: =IF('Ape02'!L5 <> Ape02_Sveta!L5 , CONCAT(CONCAT('Ape02'!L5 , "|") , Ape02_Sveta!L5 ) , 'Ape02'!L5)
A6: =IF('Ape02'!A6 <> Ape02_Sveta!A6 , CONCAT(CONCAT('Ape02'!A6 , "|") , Ape02_Sveta!A6 ) , 'Ape02'!A6) -> 5 | B6: =IF('Ape02'!B6 <> Ape02_Sveta!B6 , CONCAT(CONCAT('Ape02'!B6 , "|") , Ape02_Sveta!B6 ) , 'Ape02'!B6) -> Groom me | C6: =IF('Ape02'!C6 <> Ape02_Sveta!C6 , CONCAT(CONCAT('Ape02'!C6 , "|") , Ape02_Sveta!C6 ) , 'Ape02'!C6) -> Scratch me here | D6: =IF('Ape02'!D6 <> Ape02_Sveta!D6 , CONCAT(CONCAT('Ape02'!D6 , "|") , Ape02_Sveta!D6 ) , 'Ape02'!D6) -> 1 | E6: =IF('Ape02'!E6 <> Ape02_Sveta!E6 , CONCAT(CONCAT('Ape02'!E6 , "|") , Ape02_Sveta!E6 ) , 'Ape02'!E6) -> fun | F6: =IF('Ape02'!F6 <> Ape02_Sveta!F6 , CONCAT(CONCAT('Ape02'!F6 , "|") , Ape02_Sveta!F6 ) , 'Ape02'!F6) -> 0 | G6: =IF('Ape02'!G6 <> Ape02_Sveta!G6 , CONCAT(CONCAT('Ape02'!G6 , "|") , Ape02_Sveta!G6 ) , 'Ape02'!G6) -> Tired | H6: =IF('Ape02'!H6 <> Ape02_Sveta!H6 , CONCAT(CONCAT('Ape02'!H6 , "|") , Ape02_Sveta!H6 ) , 'Ape02'!H6) -> 0 | ... L6: =IF('Ape02'!L6 <> Ape02_Sveta!L6 , CONCAT(CONCAT('Ape02'!L6 , "|") , Ape02_Sveta!L6 ) , 'Ape02'!L6)
A7: =IF('Ape02'!A7 <> Ape02_Sveta!A7 , CONCAT(CONCAT('Ape02'!A7 , "|") , Ape02_Sveta!A7 ) , 'Ape02'!A7) -> 6 | B7: =IF('Ape02'!B7 <> Ape02_Sveta!B7 , CONCAT(CONCAT('Ape02'!B7 , "|") , Ape02_Sveta!B7 ) , 'Ape02'!B7) -> Climb on my back | C7: =IF('Ape02'!C7 <> Ape02_Sveta!C7 , CONCAT(CONCAT('Ape02'!C7 , "|") , Ape02_Sveta!C7 ) , 'Ape02'!C7) -> Caution | D7: =IF('Ape02'!D7 <> Ape02_Sveta!D7 , CONCAT(CONCAT('Ape02'!D7 , "|") , Ape02_Sveta!D7 ) , 'Ape02'!D7) -> 0 | E7: =IF('Ape02'!E7 <> Ape02_Sveta!E7 , CONCAT(CONCAT('Ape02'!E7 , "|") , Ape02_Sveta!E7 ) , 'Ape02'!E7) -> protect | F7: =IF('Ape02'!F7 <> Ape02_Sveta!F7 , CONCAT(CONCAT('Ape02'!F7 , "|") , Ape02_Sveta!F7 ) , 'Ape02'!F7) -> 0 | G7: =IF('Ape02'!G7 <> Ape02_Sveta!G7 , CONCAT(CONCAT('Ape02'!G7 , "|") , Ape02_Sveta!G7 ) , 'Ape02'!G7) -> Stop | H7: =IF('Ape02'!H7 <> Ape02_Sveta!H7 , CONCAT(CONCAT('Ape02'!H7 , "|") , Ape02_Sveta!H7 ) , 'Ape02'!H7) -> 0 | ... L7: =IF('Ape02'!L7 <> Ape02_Sveta!L7 , CONCAT(CONCAT('Ape02'!L7 , "|") , Ape02_Sveta!L7 ) , 'Ape02'!L7)
A8: =IF('Ape02'!A8 <> Ape02_Sveta!A8 , CONCAT(CONCAT('Ape02'!A8 , "|") , Ape02_Sveta!A8 ) , 'Ape02'!A8) -> 7 | B8: =IF('Ape02'!B8 <> Ape02_Sveta!B8 , CONCAT(CONCAT('Ape02'!B8 , "|") , Ape02_Sveta!B8 ) , 'Ape02'!B8) -> Move into a new position | C8: =IF('Ape02'!C8 <> Ape02_Sveta!C8 , CONCAT(CONCAT('Ape02'!C8 , "|") , Ape02_Sveta!C8 ) , 'Ape02'!C8) -> Don't touch there? | D8: =IF('Ape02'!D8 <> Ape02_Sveta!D8 , CONCAT(CONCAT('Ape02'!D8 , "|") , Ape02_Sveta!D8 ) , 'Ape02'!D8) -> 0 | E8: =IF('Ape02'!E8 <> Ape02_Sveta!E8 , CONCAT(CONCAT('Ape02'!E8 , "|") , Ape02_Sveta!E8 ) , 'Ape02'!E8) -> play | F8: =IF('Ape02'!F8 <> Ape02_Sveta!F8 , CONCAT(CONCAT('Ape02'!F8 , "|") , Ape02_Sveta!F8 ) , 'Ape02'!F8) -> 0 | G8: =IF('Ape02'!G8 <> Ape02_Sveta!G8 , CONCAT(CONCAT('Ape02'!G8 , "|") , Ape02_Sveta!G8 ) , 'Ape02'!G8) -> Angry | H8: =IF('Ape02'!H8 <> Ape02_Sveta!H8 , CONCAT(CONCAT('Ape02'!H8 , "|") , Ape02_Sveta!H8 ) , 'Ape02'!H8) -> 0 | ... L8: =IF('Ape02'!L8 <> Ape02_Sveta!L8 , CONCAT(CONCAT('Ape02'!L8 , "|") , Ape02_Sveta!L8 ) , 'Ape02'!L8)
A9: =IF('Ape02'!A9 <> Ape02_Sveta!A9 , CONCAT(CONCAT('Ape02'!A9 , "|") , Ape02_Sveta!A9 ) , 'Ape02'!A9) -> 8 | B9: =IF('Ape02'!B9 <> Ape02_Sveta!B9 , CONCAT(CONCAT('Ape02'!B9 , "|") , Ape02_Sveta!B9 ) , 'Ape02'!B9) -> Give me that food | C9: =IF('Ape02'!C9 <> Ape02_Sveta!C9 , CONCAT(CONCAT('Ape02'!C9 , "|") , Ape02_Sveta!C9 ) , 'Ape02'!C9) -> Food for me? | D9: =IF('Ape02'!D9 <> Ape02_Sveta!D9 , CONCAT(CONCAT('Ape02'!D9 , "|") , Ape02_Sveta!D9 ) , 'Ape02'!D9) -> 1|0 | E9: =IF('Ape02'!E9 <> Ape02_Sveta!E9 , CONCAT(CONCAT('Ape02'!E9 , "|") , Ape02_Sveta!E9 ) , 'Ape02'!E9) -> need food | F9: =IF('Ape02'!F9 <> Ape02_Sveta!F9 , CONCAT(CONCAT('Ape02'!F9 , "|") , Ape02_Sveta!F9 ) , 'Ape02'!F9) -> 1 | G9: =IF('Ape02'!G9 <> Ape02_Sveta!G9 , CONCAT(CONCAT('Ape02'!G9 , "|") , Ape02_Sveta!G9 ) , 'Ape02'!G9) -> Stop | H9: =IF('Ape02'!H9 <> Ape02_Sveta!H9 , CONCAT(CONCAT('Ape02'!H9 , "|") , Ape02_Sveta!H9 ) , 'Ape02'!H9) -> 0 | ... L9: =IF('Ape02'!L9 <> Ape02_Sveta!L9 , CONCAT(CONCAT('Ape02'!L9 , "|") , Ape02_Sveta!L9 ) , 'Ape02'!L9)
A10: =IF('Ape02'!A10 <> Ape02_Sveta!A10 , CONCAT(CONCAT('Ape02'!A10 , "|") , Ape02_Sveta!A10 ) , 'Ape02'!A10) -> 9 | B10: =IF('Ape02'!B10 <> Ape02_Sveta!B10 , CONCAT(CONCAT('Ape02'!B10 , "|") , Ape02_Sveta!B10 ) , 'Ape02'!B10) -> Give me that food | C10: =IF('Ape02'!C10 <> Ape02_Sveta!C10 , CONCAT(CONCAT('Ape02'!C10 , "|") , Ape02_Sveta!C10 ) , 'Ape02'!C10) -> Hungry (Share?) | D10: =IF('Ape02'!D10 <> Ape02_Sveta!D10 , CONCAT(CONCAT('Ape02'!D10 , "|") , Ape02_Sveta!D10 ) , 'Ape02'!D10) -> 1 | E10: =IF('Ape02'!E10 <> Ape02_Sveta!E10 , CONCAT(CONCAT('Ape02'!E10 , "|") , Ape02_Sveta!E10 ) , 'Ape02'!E10) -> need food | F10: =IF('Ape02'!F10 <> Ape02_Sveta!F10 , CONCAT(CONCAT('Ape02'!F10 , "|") , Ape02_Sveta!F10 ) , 'Ape02'!F10) -> 1 | G10: =IF('Ape02'!G10 <> Ape02_Sveta!G10 , CONCAT(CONCAT('Ape02'!G10 , "|") , Ape02_Sveta!G10 ) , 'Ape02'!G10) -> Don't move | H10: =IF('Ape02'!H10 <> Ape02_Sveta!H10 , CONCAT(CONCAT('Ape02'!H10 , "|") , Ape02_Sveta!H10 ) , 'Ape02'!H10) -> 0 | ... L10: =IF('Ape02'!L10 <> Ape02_Sveta!L10 , CONCAT(CONCAT('Ape02'!L10 , "|") , Ape02_Sveta!L10 ) , 'Ape02'!L10)
A11: =IF('Ape02'!A11 <> Ape02_Sveta!A11 , CONCAT(CONCAT('Ape02'!A11 , "|") , Ape02_Sveta!A11 ) , 'Ape02'!A11) -> 10 | B11: =IF('Ape02'!B11 <> Ape02_Sveta!B11 , CONCAT(CONCAT('Ape02'!B11 , "|") , Ape02_Sveta!B11 ) , 'Ape02'!B11) -> Groom me | C11: =IF('Ape02'!C11 <> Ape02_Sveta!C11 , CONCAT(CONCAT('Ape02'!C11 , "|") , Ape02_Sveta!C11 ) , 'Ape02'!C11) -> Stay away | D11: =IF('Ape02'!D11 <> Ape02_Sveta!D11 , CONCAT(CONCAT('Ape02'!D11 , "|") , Ape02_Sveta!D11 ) , 'Ape02'!D11) -> 0 | E11: =IF('Ape02'!E11 <> Ape02_Sveta!E11 , CONCAT(CONCAT('Ape02'!E11 , "|") , Ape02_Sveta!E11 ) , 'Ape02'!E11) -> searching food | F11: =IF('Ape02'!F11 <> Ape02_Sveta!F11 , CONCAT(CONCAT('Ape02'!F11 , "|") , Ape02_Sveta!F11 ) , 'Ape02'!F11) -> 0 | G11: =IF('Ape02'!G11 <> Ape02_Sveta!G11 , CONCAT(CONCAT('Ape02'!G11 , "|") , Ape02_Sveta!G11 ) , 'Ape02'!G11) -> Climbing on | H11: =IF('Ape02'!H11 <> Ape02_Sveta!H11 , CONCAT(CONCAT('Ape02'!H11 , "|") , Ape02_Sveta!H11 ) , 'Ape02'!H11) -> 0 | ... L11: =IF('Ape02'!L11 <> Ape02_Sveta!L11 , CONCAT(CONCAT('Ape02'!L11 , "|") , Ape02_Sveta!L11 ) , 'Ape02'!L11)
A12: =IF('Ape02'!A12 <> Ape02_Sveta!A12 , CONCAT(CONCAT('Ape02'!A12 , "|") , Ape02_Sveta!A12 ) , 'Ape02'!A12) -> 11 | B12: =IF('Ape02'!B12 <> Ape02_Sveta!B12 , CONCAT(CONCAT('Ape02'!B12 , "|") , Ape02_Sveta!B12 ) , 'Ape02'!B12) -> Climb on my back | C12: =IF('Ape02'!C12 <> Ape02_Sveta!C12 , CONCAT(CONCAT('Ape02'!C12 , "|") , Ape02_Sveta!C12 ) , 'Ape02'!C12) -> Jump on my back | D12: =IF('Ape02'!D12 <> Ape02_Sveta!D12 , CONCAT(CONCAT('Ape02'!D12 , "|") , Ape02_Sveta!D12 ) , 'Ape02'!D12) -> 2 | E12: =IF('Ape02'!E12 <> Ape02_Sveta!E12 , CONCAT(CONCAT('Ape02'!E12 , "|") , Ape02_Sveta!E12 ) , 'Ape02'!E12) -> help | F12: =IF('Ape02'!F12 <> Ape02_Sveta!F12 , CONCAT(CONCAT('Ape02'!F12 , "|") , Ape02_Sveta!F12 ) , 'Ape02'!F12) -> 0 | G12: =IF('Ape02'!G12 <> Ape02_Sveta!G12 , CONCAT(CONCAT('Ape02'!G12 , "|") , Ape02_Sveta!G12 ) , 'Ape02'!G12) -> Danger | H12: =IF('Ape02'!H12 <> Ape02_Sveta!H12 , CONCAT(CONCAT('Ape02'!H12 , "|") , Ape02_Sveta!H12 ) , 'Ape02'!H12) -> 0 | ... L12: =IF('Ape02'!L12 <> Ape02_Sveta!L12 , CONCAT(CONCAT('Ape02'!L12 , "|") , Ape02_Sveta!L12 ) , 'Ape02'!L12)
... A26: =IF('Ape02'!A26 <> Ape02_Sveta!A26 , CONCAT(CONCAT('Ape02'!A26 , "|") , Ape02_Sveta!A26 ) , 'Ape02'!A26) | B26: =IF('Ape02'!B26 <> Ape02_Sveta!B26 , CONCAT(CONCAT('Ape02'!B26 , "|") , Ape02_Sveta!B26 ) , 'Ape02'!B26) | C26: =IF('Ape02'!C26 <> Ape02_Sveta!C26 , CONCAT(CONCAT('Ape02'!C26 , "|") , Ape02_Sveta!C26 ) , 'Ape02'!C26) | D26: =IF('Ape02'!D26 <> Ape02_Sveta!D26 , CONCAT(CONCAT('Ape02'!D26 , "|") , Ape02_Sveta!D26 ) , 'Ape02'!D26) | E26: =IF('Ape02'!E26 <> Ape02_Sveta!E26 , CONCAT(CONCAT('Ape02'!E26 , "|") , Ape02_Sveta!E26 ) , 'Ape02'!E26) | F26: =IF('Ape02'!F26 <> Ape02_Sveta!F26 , CONCAT(CONCAT('Ape02'!F26 , "|") , Ape02_Sveta!F26 ) , 'Ape02'!F26) | G26: =IF('Ape02'!G26 <> Ape02_Sveta!G26 , CONCAT(CONCAT('Ape02'!G26 , "|") , Ape02_Sveta!G26 ) , 'Ape02'!G26) | H26: =IF('Ape02'!H26 <> Ape02_Sveta!H26 , CONCAT(CONCAT('Ape02'!H26 , "|") , Ape02_Sveta!H26 ) , 'Ape02'!H26) | ... L26: =IF('Ape02'!L26 <> Ape02_Sveta!L26 , CONCAT(CONCAT('Ape02'!L26 , "|") , Ape02_Sveta!L26 ) , 'Ape02'!L26)

Sheet Vocalizations_Sveta
A1: Trial id | B1: Right answer | C1: Participant 1 | D1: Rating P1 | E1: Participant 2 | F1: Rating P2 | G1: Participant 3 | H1: Rating P3 | I1: Participant 4 | J1: Rating P4
A2: 1 | B2: gather | C2: I love you | D2: 0 | E2: i dont know | F2: 0 | G2: over there | H2: 0 | I2: talk | J2: 0
A3: 2 | B3: bad | C3: Yuck | D3: 0 | E3: Discusting | F3: 1 | G3: 0 | I3: scare | J3: 0
A4: 3 | B4: big | C4: Understanding | D4: 0 | E4: entusiasm | F4: 0 | G4: big | H4: 3 | I4: sleep | J4: 0
A5: 4 | B5: dull | C5: Disatisfied | D5: 0 | E5: understand | F5: 0 | G5: tired | H5: 0 | I5: sleep | J5: 0
A6: 5 | B6: hunt | C6: Frustration | D6: 0 | E6: angry | F6: 0 | G6: waking up | H6: 0 | I6: scare | J6: 0
A7: 6 | B7: knife | C7: Fast/fighting | D7: 0 | E7: wind | F7: 0 | G7: fight | H7: 0 | I7: attention | J7: 0
A8: 7 | B8: man | C8: Shivers of disgust | D8: 0 | E8: angry | F8: 0 | G8: now | H8: 0 | I8: scare | J8: 0
A9: 8 | B9: meat | C9: Good food | D9: 1 | E9: angry eat | F9: 0 | G9: went that way | H9: 0 | I9: eat | J9: 0
A10: 9 | B10: one | C10: Short no | D10: 0 | E10: indeference | F10: 0 | G10: yes | H10: 0 | I10: eat | J10: 0
A11: 10 | B11: snake | C11: Hot | D11: 0 | E11: touch something hot | F11: 0 | G11: hissing snake | H11: 3 | I11: attention | J11: 0
A12: 11 | B12: that | C12: Mild agree | D12: 0 | E12: understand | F12: 0 | G12: surprise | H12: 0 | I12: attention | J12: 0
A13: 12 | B13: tiger | C13: Aggressive | D13: 0 | E13: animal attack | F13: 0 | G13: growl | H13: 0 | I13: scare | J13: 0
A14: 13 | B14: woman | C14: Exictement and surprise | D14: 0 | E14: wow | F14: 0 | G14: ooh | H14: 0 | I14: attention | J14: 0
A15: 14 | B15: bad | C15: Angry | D15: 0 | E15: i dont know | F15: 0 | G15: anger | H15: 0 | I15: scare | J15: 0
... A91: 90 | B91: small | C91: Do it | D91: 0 | E91: i dont know | F91: 0 | G91: quick | H91: 0 | I91: attention | J91: 0

Sheet Ape01_Sveta
A1: Trial Id | B1: Right answer | C1: Participant 1 | D1: Rating P1 | E1: Participant 2 | F1: Rating P2 | G1: Participant 3 | H1: Rating P3
A2: 1 | B2: Groom me | C2: Hold on | D2: 0 | E2: Scratching himself | F2: 0 | G2: check my back | H2: 2
A3: 2 | B3: Groom me | C3: sit here | D3: 0 | E3: Alert | F3: 0 | G3: its my territory | H3: 0
A4: 3 | B4: Carry me | C4: astonishment | D4: 0 | E4: Relaxation | F4: 0 | G4: feel comfy | H4: 0
A5: 4 | B5: Give me that food | C5: defending | D5: 0 | E5: Asks for something | F5: 0 | G5: attention pls | H5: 0
A6: 5 | B6: Groom me | C6: superiority | D6: 0 | E6: Asking someone to clean him | F6: 2 | G6: just scratching, feel comfy | H6: 0
A7: 6 | B7: Climb on my back | C7: get away | D7: 0 | E7: Cleaning his kid | F7: 0 | G7: poking | H7: 0
A8: 7 | B8: Move into a new position | C8: get down | D8: 0 | E8: Pushing him to climb up | F8: 0 | G8: keeping close | H8: 0
A9: 8 | B9: Give me that food | C9: eat | D9: 0 | E9: Seeing what he eats | F9: 0 | G9: checking what he's eating | H9: 0
A10: 9 | B10: Give me that food | C10: frienship | D10: 0 | E10: Cleans his partner | F10: 0 | G10: he's bored | H10: 0
A11: 10 | B11: Let's have sex | C11: get food | D11: 0 | E11: Sign of aggression | F11: 0 | G11: danger | H11: 0
A12: 11 | B12: Move away from me | C12: scare something | D12: 0 | E12: Tells him to go away | F12: 2 | G12: watch out | H12: 0
A13: 12 | B13: Climb on my back | C13: be careful | D13: 0 | E13: Playing | F13: 0 | G13: playing around | H13: 0
... A21: 20 | B21: Let's be friendly | C21: courtship | D21: 0 | E21: Telling him to come here | F21: 0 | G21: checking | H21: 0

Sheet Ape02_Sveta
A1: Trial Id | B1: Right answer | C1: Participant 1 | D1: Rating P1 | E1: Participant 2 | F1: Rating P2 | G1: Participant 3 | H1: Rating P3
A2: 1 | B2: Let's have sex | C2: Time for love? | D2: 2 | E2: fun | F2: 0 | G2: Hunting | H2: 0
A3: 2 | B3: Groom me | C3: Scratch me under my arm | D3: 1 | E3: fun | F3: 0 | G3: Sleepy | H3: 0
A4: 3 | B4: Give me that food | C4: Im hungry | D4: 0 | E4: fun | F4: 0 | G4: Let's go | H4: 0
A5: 4 | B5: Groom me | C5: Scratching side | D5: 0 | E5: power | F5: 0 | G5: Hungry | H5: 0
A6: 5 | B6: Groom me | C6: Scratch me here | D6: 1 | E6: fun | F6: 0 | G6: Tired | H6: 0
A7: 6 | B7: Climb on my back | C7: Caution | D7: 0 | E7: protect | F7: 0 | G7: Stop | H7: 0
A8: 7 | B8: Move into a new position | C8: Don't touch there? | D8: 0 | E8: play | F8: 0 | G8: Angry | H8: 0
A9: 8 | B9: Give me that food | C9: Food for me? | D9: 0 | E9: need food | F9: 1 | G9: Stop | H9: 0
A10: 9 | B10: Give me that food | C10: Hungry (Share?) | D10: 1 | E10: need food | F10: 1 | G10: Don't move | H10: 0
A11: 10 | B11: Groom me | C11: Stay away | D11: 0 | E11: searching food | F11: 0 | G11: Climbing on | H11: 0
A12: 11 | B12: Climb on my back | C12: Jump on my back | D12: 2 | E12: help | F12: 0 | G12: Danger | H12: 0
